Workbook

Sheet Datos
A1: archivo | B1: marcos | C1: politica | D1: resultado | E1: Matriz | F1: TP | G1: NR | H1: Fallas | I1: Exitosos | J1: Tasa fallas | K1: Tiempo (s) | M1: Supuestos: NR es 6·NF·NC·pasadas. Como la matriz es cuadrada y se hizo 1 pasada, queda 6·Matriz² Supuesto 2: El tiempo cuenta cada acierto a 100 ns y cada falla a 8 ms.
A2: ref_128_1024 | B2: 4 | C2: FIFO | D2: ********Proceso 1 Total accesos 100884 Total fallos 2580 | E2: =VALUE(MID(A2,5,SEARCH("_",A2,5)-5)) -> 128 | F2: =VALUE(MID(A2,SEARCH("_",A2,5)+1,10)) -> 1024 | G2: =6*E2^2 -> 98304 | H2: =VALUE(MID(D2,SEARCH("fallos",D2)+7,20)) -> 2580 | I2: =G2-H2 -> 95724 | J2: =H2/G2 -> 0.026245117 | K2: =I2*0.0000001+H2*0.008 -> 20.649572
A3: ref_128_1024 | B3: 4 | C3: FIFOModified | D3: ********Proceso 1 Total accesos 100369 Total fallos 2065 | E3: =VALUE(MID(A3,5,SEARCH("_",A3,5)-5)) -> 128 | F3: =VALUE(MID(A3,SEARCH("_",A3,5)+1,10)) -> 1024 | G3: =6*E3^2 -> 98304 | H3: =VALUE(MID(D3,SEARCH("fallos",D3)+7,20)) -> 2065 | I3: =G3-H3 -> 96239 | J3: =H3/G3 -> 0.021006266 | K3: =I3*0.0000001+H3*0.008 -> 16.529624
A4: ref_128_1024 | B4: 4 | C4: LRU | D4: ********Proceso 1 Total accesos 100369 Total fallos 2065 | E4: =VALUE(MID(A4,5,SEARCH("_",A4,5)-5)) -> 128 | F4: =VALUE(MID(A4,SEARCH("_",A4,5)+1,10)) -> 1024 | G4: =6*E4^2 -> 98304 | H4: =VALUE(MID(D4,SEARCH("fallos",D4)+7,20)) -> 2065 | I4: =G4-H4 -> 96239 | J4: =H4/G4 -> 0.021006266 | K4: =I4*0.0000001+H4*0.008 -> 16.529624
A5: ref_128_1024 | B5: 8 | C5: FIFO | D5: ********Proceso 1 Total accesos 100626 Total fallos 2322 | E5: =VALUE(MID(A5,5,SEARCH("_",A5,5)-5)) -> 128 | F5: =VALUE(MID(A5,SEARCH("_",A5,5)+1,10)) -> 1024 | G5: =6*E5^2 -> 98304 | H5: =VALUE(MID(D5,SEARCH("fallos",D5)+7,20)) -> 2322 | I5: =G5-H5 -> 95982 | J5: =H5/G5 -> 0.023620605 | K5: =I5*0.0000001+H5*0.008 -> 18.585598
A6: ref_128_1024 | B6: 8 | C6: FIFOModified | D6: ********Proceso 1 Total accesos 100369 Total fallos 2065 | E6: =VALUE(MID(A6,5,SEARCH("_",A6,5)-5)) -> 128 | F6: =VALUE(MID(A6,SEARCH("_",A6,5)+1,10)) -> 1024 | G6: =6*E6^2 -> 98304 | H6: =VALUE(MID(D6,SEARCH("fallos",D6)+7,20)) -> 2065 | I6: =G6-H6 -> 96239 | J6: =H6/G6 -> 0.021006266 | K6: =I6*0.0000001+H6*0.008 -> 16.529624
A7: ref_128_1024 | B7: 8 | C7: LRU | D7: ********Proceso 1 Total accesos 100369 Total fallos 2065 | E7: =VALUE(MID(A7,5,SEARCH("_",A7,5)-5)) -> 128 | F7: =VALUE(MID(A7,SEARCH("_",A7,5)+1,10)) -> 1024 | G7: =6*E7^2 -> 98304 | H7: =VALUE(MID(D7,SEARCH("fallos",D7)+7,20)) -> 2065 | I7: =G7-H7 -> 96239 | J7: =H7/G7 -> 0.021006266 | K7: =I7*0.0000001+H7*0.008 -> 16.529624
A8: ref_128_1024 | B8: 16 | C8: FIFO | D8: ********Proceso 1 Total accesos 100497 Total fallos 2193 | E8: =VALUE(MID(A8,5,SEARCH("_",A8,5)-5)) -> 128 | F8: =VALUE(MID(A8,SEARCH("_",A8,5)+1,10)) -> 1024 | G8: =6*E8^2 -> 98304 | H8: =VALUE(MID(D8,SEARCH("fallos",D8)+7,20)) -> 2193 | I8: =G8-H8 -> 96111 | J8: =H8/G8 -> 0.02230835 | K8: =I8*0.0000001+H8*0.008 -> 17.553611
A9: ref_128_1024 | B9: 16 | C9: FIFOModified | D9: ********Proceso 1 Total accesos 100369 Total fallos 2065 | E9: =VALUE(MID(A9,5,SEARCH("_",A9,5)-5)) -> 128 | F9: =VALUE(MID(A9,SEARCH("_",A9,5)+1,10)) -> 1024 | G9: =6*E9^2 -> 98304 | H9: =VALUE(MID(D9,SEARCH("fallos",D9)+7,20)) -> 2065 | I9: =G9-H9 -> 96239 | J9: =H9/G9 -> 0.021006266 | K9: =I9*0.0000001+H9*0.008 -> 16.529624 | M9: Grafica de Tiempos vs Marcos: Caso especifico 128 debido a que es donde mas se ve esta diferencia
A10: ref_128_1024 | B10: 16 | C10: LRU | D10: ********Proceso 1 Total accesos 100369 Total fallos 2065 | E10: =VALUE(MID(A10,5,SEARCH("_",A10,5)-5)) -> 128 | F10: =VALUE(MID(A10,SEARCH("_",A10,5)+1,10)) -> 1024 | G10: =6*E10^2 -> 98304 | H10: =VALUE(MID(D10,SEARCH("fallos",D10)+7,20)) -> 2065 | I10: =G10-H10 -> 96239 | J10: =H10/G10 -> 0.021006266 | K10: =I10*0.0000001+H10*0.008 -> 16.529624
A11: ref_128_256 | B11: 4 | C11: FIFO | D11: ********Proceso 1 Total accesos 108624 Total fallos 10320 | E11: =VALUE(MID(A11,5,SEARCH("_",A11,5)-5)) -> 128 | F11: =VALUE(MID(A11,SEARCH("_",A11,5)+1,10)) -> 256 | G11: =6*E11^2 -> 98304 | H11: =VALUE(MID(D11,SEARCH("fallos",D11)+7,20)) -> 10320 | I11: =G11-H11 -> 87984 | J11: =H11/G11 -> 0.10498047 | K11: =I11*0.0000001+H11*0.008 -> 82.568798 | M11: Matriz | N11: 128 | O11: TP | P11: 64
A12: ref_128_256 | B12: 4 | C12: FIFOModified | D12: ********Proceso 1 Total accesos 106561 Total fallos 8257 | E12: =VALUE(MID(A12,5,SEARCH("_",A12,5)-5)) -> 128 | F12: =VALUE(MID(A12,SEARCH("_",A12,5)+1,10)) -> 256 | G12: =6*E12^2 -> 98304 | H12: =VALUE(MID(D12,SEARCH("fallos",D12)+7,20)) -> 8257 | I12: =G12-H12 -> 90047 | J12: =H12/G12 -> 0.083994548 | K12: =I12*0.0000001+H12*0.008 -> 66.065005 | O12: FIFO | P12: FIFOModified | Q12: LRU
A13: ref_128_256 | B13: 4 | C13: LRU | D13: ********Proceso 1 Total accesos 106561 Total fallos 8257 | E13: =VALUE(MID(A13,5,SEARCH("_",A13,5)-5)) -> 128 | F13: =VALUE(MID(A13,SEARCH("_",A13,5)+1,10)) -> 256 | G13: =6*E13^2 -> 98304 | H13: =VALUE(MID(D13,SEARCH("fallos",D13)+7,20)) -> 8257 | I13: =G13-H13 -> 90047 | J13: =H13/G13 -> 0.083994548 | K13: =I13*0.0000001+H13*0.008 -> 66.065005 | N13: 4 | O13: =SUMIFS($K:$K,$E:$E,$N$11,$F:$F,$P$11,$B:$B,$N13,$C:$C,O$12) -> 166.91974 | P13: =SUMIFS($K:$K,$E:$E,$N$11,$F:$F,$P$11,$B:$B,$N13,$C:$C,P$12) -> 137.22412 | Q13: =SUMIFS($K:$K,$E:$E,$N$11,$F:$F,$P$11,$B:$B,$N13,$C:$C,Q$12) -> 137.22412
A14: ref_128_256 | B14: 8 | C14: FIFO | D14: ********Proceso 1 Total accesos 107592 Total fallos 9288 | E14: =VALUE(MID(A14,5,SEARCH("_",A14,5)-5)) -> 128 | F14: =VALUE(MID(A14,SEARCH("_",A14,5)+1,10)) -> 256 | G14: =6*E14^2 -> 98304 | H14: =VALUE(MID(D14,SEARCH("fallos",D14)+7,20)) -> 9288 | I14: =G14-H14 -> 89016 | J14: =H14/G14 -> 0.094482422 | K14: =I14*0.0000001+H14*0.008 -> 74.312902 | N14: 8 | O14: =SUMIFS($K:$K,$E:$E,$N$11,$F:$F,$P$11,$B:$B,$N14,$C:$C,O$12) -> 150.02396 | P14: =SUMIFS($K:$K,$E:$E,$N$11,$F:$F,$P$11,$B:$B,$N14,$C:$C,P$12) -> 135.18414 | Q14: =SUMIFS($K:$K,$E:$E,$N$11,$F:$F,$P$11,$B:$B,$N14,$C:$C,Q$12) -> 135.18414
A15: ref_128_256 | B15: 8 | C15: FIFOModified | D15: ********Proceso 1 Total accesos 106561 Total fallos 8257 | E15: =VALUE(MID(A15,5,SEARCH("_",A15,5)-5)) -> 128 | F15: =VALUE(MID(A15,SEARCH("_",A15,5)+1,10)) -> 256 | G15: =6*E15^2 -> 98304 | H15: =VALUE(MID(D15,SEARCH("fallos",D15)+7,20)) -> 8257 | I15: =G15-H15 -> 90047 | J15: =H15/G15 -> 0.083994548 | K15: =I15*0.0000001+H15*0.008 -> 66.065005 | N15: 16 | O15: =SUMIFS($K:$K,$E:$E,$N$11,$F:$F,$P$11,$B:$B,$N15,$C:$C,O$12) -> 141.57606 | P15: =SUMIFS($K:$K,$E:$E,$N$11,$F:$F,$P$11,$B:$B,$N15,$C:$C,P$12) -> 135.18414 | Q15: =SUMIFS($K:$K,$E:$E,$N$11,$F:$F,$P$11,$B:$B,$N15,$C:$C,Q$12) -> 135.18414
A16: ref_128_256 | B16: 8 | C16: LRU | D16: ********Proceso 1 Total accesos 106561 Total fallos 8257 | E16: =VALUE(MID(A16,5,SEARCH("_",A16,5)-5)) -> 128 | F16: =VALUE(MID(A16,SEARCH("_",A16,5)+1,10)) -> 256 | G16: =6*E16^2 -> 98304 | H16: =VALUE(MID(D16,SEARCH("fallos",D16)+7,20)) -> 8257 | I16: =G16-H16 -> 90047 | J16: =H16/G16 -> 0.083994548 | K16: =I16*0.0000001+H16*0.008 -> 66.065005
A17: ref_128_256 | B17: 16 | C17: FIFO | D17: ********Proceso 1 Total accesos 107076 Total fallos 8772 | E17: =VALUE(MID(A17,5,SEARCH("_",A17,5)-5)) -> 128 | F17: =VALUE(MID(A17,SEARCH("_",A17,5)+1,10)) -> 256 | G17: =6*E17^2 -> 98304 | H17: =VALUE(MID(D17,SEARCH("fallos",D17)+7,20)) -> 8772 | I17: =G17-H17 -> 89532 | J17: =H17/G17 -> 0.089233398 | K17: =I17*0.0000001+H17*0.008 -> 70.184953
A18: ref_128_256 | B18: 16 | C18: FIFOModified | D18: ********Proceso 1 Total accesos 106561 Total fallos 8257 | E18: =VALUE(MID(A18,5,SEARCH("_",A18,5)-5)) -> 128 | F18: =VALUE(MID(A18,SEARCH("_",A18,5)+1,10)) -> 256 | G18: =6*E18^2 -> 98304 | H18: =VALUE(MID(D18,SEARCH("fallos",D18)+7,20)) -> 8257 | I18: =G18-H18 -> 90047 | J18: =H18/G18 -> 0.083994548 | K18: =I18*0.0000001+H18*0.008 -> 66.065005 | M18: Matriz | N18: 128 | O18: TP | P18: 256
A19: ref_128_256 | B19: 16 | C19: LRU | D19: ********Proceso 1 Total accesos 106561 Total fallos 8257 | E19: =VALUE(MID(A19,5,SEARCH("_",A19,5)-5)) -> 128 | F19: =VALUE(MID(A19,SEARCH("_",A19,5)+1,10)) -> 256 | G19: =6*E19^2 -> 98304 | H19: =VALUE(MID(D19,SEARCH("fallos",D19)+7,20)) -> 8257 | I19: =G19-H19 -> 90047 | J19: =H19/G19 -> 0.083994548 | K19: =I19*0.0000001+H19*0.008 -> 66.065005 | O19: FIFO | P19: FIFOModified | Q19: LRU
A20: ref_128_64 | B20: 4 | C20: FIFO | D20: ********Proceso 1 Total accesos 119168 Total fallos 20864 | E20: =VALUE(MID(A20,5,SEARCH("_",A20,5)-5)) -> 128 | F20: =VALUE(MID(A20,SEARCH("_",A20,5)+1,10)) -> 64 | G20: =6*E20^2 -> 98304 | H20: =VALUE(MID(D20,SEARCH("fallos",D20)+7,20)) -> 20864 | I20: =G20-H20 -> 77440 | J20: =H20/G20 -> 0.21223958 | K20: =I20*0.0000001+H20*0.008 -> 166.91974 | N20: 4 | O20: =SUMIFS($K:$K,$E:$E,$N$11,$F:$F,$P$18,$B:$B,$N20,$C:$C,O$12) -> 82.568798 | P20: =SUMIFS($K:$K,$E:$E,$N$11,$F:$F,$P$18,$B:$B,$N20,$C:$C,P$12) -> 66.065005 | Q20: =SUMIFS($K:$K,$E:$E,$N$11,$F:$F,$P$18,$B:$B,$N20,$C:$C,Q$12) -> 66.065005
A21: ref_128_64 | B21: 4 | C21: FIFOModified | D21: ********Proceso 1 Total accesos 115456 Total fallos 17152 | E21: =VALUE(MID(A21,5,SEARCH("_",A21,5)-5)) -> 128 | F21: =VALUE(MID(A21,SEARCH("_",A21,5)+1,10)) -> 64 | G21: =6*E21^2 -> 98304 | H21: =VALUE(MID(D21,SEARCH("fallos",D21)+7,20)) -> 17152 | I21: =G21-H21 -> 81152 | J21: =H21/G21 -> 0.17447917 | K21: =I21*0.0000001+H21*0.008 -> 137.22412 | N21: 8 | O21: =SUMIFS($K:$K,$E:$E,$N$11,$F:$F,$P$18,$B:$B,$N21,$C:$C,O$12) -> 74.312902 | P21: =SUMIFS($K:$K,$E:$E,$N$11,$F:$F,$P$18,$B:$B,$N21,$C:$C,P$12) -> 66.065005 | Q21: =SUMIFS($K:$K,$E:$E,$N$11,$F:$F,$P$18,$B:$B,$N21,$C:$C,Q$12) -> 66.065005
A22: ref_128_64 | B22: 4 | C22: LRU | D22: ********Proceso 1 Total accesos 115456 Total fallos 17152 | E22: =VALUE(MID(A22,5,SEARCH("_",A22,5)-5)) -> 128 | F22: =VALUE(MID(A22,SEARCH("_",A22,5)+1,10)) -> 64 | G22: =6*E22^2 -> 98304 | H22: =VALUE(MID(D22,SEARCH("fallos",D22)+7,20)) -> 17152 | I22: =G22-H22 -> 81152 | J22: =H22/G22 -> 0.17447917 | K22: =I22*0.0000001+H22*0.008 -> 137.22412 | N22: 16 | O22: =SUMIFS($K:$K,$E:$E,$N$11,$F:$F,$P$18,$B:$B,$N22,$C:$C,O$12) -> 70.184953 | P22: =SUMIFS($K:$K,$E:$E,$N$11,$F:$F,$P$18,$B:$B,$N22,$C:$C,P$12) -> 66.065005 | Q22: =SUMIFS($K:$K,$E:$E,$N$11,$F:$F,$P$18,$B:$B,$N22,$C:$C,Q$12) -> 66.065005
A23: ref_128_64 | B23: 8 | C23: FIFO | D23: ********Proceso 1 Total accesos 117056 Total fallos 18752 | E23: =VALUE(MID(A23,5,SEARCH("_",A23,5)-5)) -> 128 | F23: =VALUE(MID(A23,SEARCH("_",A23,5)+1,10)) -> 64 | G23: =6*E23^2 -> 98304 | H23: =VALUE(MID(D23,SEARCH("fallos",D23)+7,20)) -> 18752 | I23: =G23-H23 -> 79552 | J23: =H23/G23 -> 0.19075521 | K23: =I23*0.0000001+H23*0.008 -> 150.02396
A24: ref_128_64 | B24: 8 | C24: FIFOModified | D24: ********Proceso 1 Total accesos 115201 Total fallos 16897 | E24: =VALUE(MID(A24,5,SEARCH("_",A24,5)-5)) -> 128 | F24: =VALUE(MID(A24,SEARCH("_",A24,5)+1,10)) -> 64 | G24: =6*E24^2 -> 98304 | H24: =VALUE(MID(D24,SEARCH("fallos",D24)+7,20)) -> 16897 | I24: =G24-H24 -> 81407 | J24: =H24/G24 -> 0.17188517 | K24: =I24*0.0000001+H24*0.008 -> 135.18414
A25: ref_128_64 | B25: 8 | C25: LRU | D25: ********Proceso 1 Total accesos 115201 Total fallos 16897 | E25: =VALUE(MID(A25,5,SEARCH("_",A25,5)-5)) -> 128 | F25: =VALUE(MID(A25,SEARCH("_",A25,5)+1,10)) -> 64 | G25: =6*E25^2 -> 98304 | H25: =VALUE(MID(D25,SEARCH("fallos",D25)+7,20)) -> 16897 | I25: =G25-H25 -> 81407 | J25: =H25/G25 -> 0.17188517 | K25: =I25*0.0000001+H25*0.008 -> 135.18414 | M25: Matriz | N25: 128 | O25: TP | P25: 1024
A26: ref_128_64 | B26: 16 | C26: FIFO | D26: ********Proceso 1 Total accesos 116000 Total fallos 17696 | E26: =VALUE(MID(A26,5,SEARCH("_",A26,5)-5)) -> 128 | F26: =VALUE(MID(A26,SEARCH("_",A26,5)+1,10)) -> 64 | G26: =6*E26^2 -> 98304 | H26: =VALUE(MID(D26,SEARCH("fallos",D26)+7,20)) -> 17696 | I26: =G26-H26 -> 80608 | J26: =H26/G26 -> 0.18001302 | K26: =I26*0.0000001+H26*0.008 -> 141.57606 | O26: FIFO | P26: FIFOModified | Q26: LRU
A27: ref_128_64 | B27: 16 | C27: FIFOModified | D27: ********Proceso 1 Total accesos 115201 Total fallos 16897 | E27: =VALUE(MID(A27,5,SEARCH("_",A27,5)-5)) -> 128 | F27: =VALUE(MID(A27,SEARCH("_",A27,5)+1,10)) -> 64 | G27: =6*E27^2 -> 98304 | H27: =VALUE(MID(D27,SEARCH("fallos",D27)+7,20)) -> 16897 | I27: =G27-H27 -> 81407 | J27: =H27/G27 -> 0.17188517 | K27: =I27*0.0000001+H27*0.008 -> 135.18414 | N27: 4 | O27: =SUMIFS($K:$K,$E:$E,$N$11,$F:$F,$P$25,$B:$B,$N27,$C:$C,O$12) -> 20.649572 | P27: =SUMIFS($K:$K,$E:$E,$N$11,$F:$F,$P$25,$B:$B,$N27,$C:$C,P$12) -> 16.529624 | Q27: =SUMIFS($K:$K,$E:$E,$N$11,$F:$F,$P$25,$B:$B,$N27,$C:$C,Q$12) -> 16.529624
A28: ref_128_64 | B28: 16 | C28: LRU | D28: ********Proceso 1 Total accesos 115201 Total fallos 16897 | E28: =VALUE(MID(A28,5,SEARCH("_",A28,5)-5)) -> 128 | F28: =VALUE(MID(A28,SEARCH("_",A28,5)+1,10)) -> 64 | G28: =6*E28^2 -> 98304 | H28: =VALUE(MID(D28,SEARCH("fallos",D28)+7,20)) -> 16897 | I28: =G28-H28 -> 81407 | J28: =H28/G28 -> 0.17188517 | K28: =I28*0.0000001+H28*0.008 -> 135.18414 | N28: 8 | O28: =SUMIFS($K:$K,$E:$E,$N$11,$F:$F,$P$25,$B:$B,$N28,$C:$C,O$12) -> 18.585598 | P28: =SUMIFS($K:$K,$E:$E,$N$11,$F:$F,$P$25,$B:$B,$N28,$C:$C,P$12) -> 16.529624 | Q28: =SUMIFS($K:$K,$E:$E,$N$11,$F:$F,$P$25,$B:$B,$N28,$C:$C,Q$12) -> 16.529624
A29: ref_16_1024 | B29: 4 | C29: FIFO | D29: ********Proceso 1 Total accesos 1537 Total fallos 1 | E29: =VALUE(MID(A29,5,SEARCH("_",A29,5)-5)) -> 16 | F29: =VALUE(MID(A29,SEARCH("_",A29,5)+1,10)) -> 1024 | G29: =6*E29^2 -> 1536 | H29: =VALUE(MID(D29,SEARCH("fallos",D29)+7,20)) -> 1 | I29: =G29-H29 -> 1535 | J29: =H29/G29 -> 0.00065104167 | K29: =I29*0.0000001+H29*0.008 -> 0.0081535 | N29: 16 | O29: =SUMIFS($K:$K,$E:$E,$N$11,$F:$F,$P$25,$B:$B,$N29,$C:$C,O$12) -> 17.553611 | P29: =SUMIFS($K:$K,$E:$E,$N$11,$F:$F,$P$25,$B:$B,$N29,$C:$C,P$12) -> 16.529624 | Q29: =SUMIFS($K:$K,$E:$E,$N$11,$F:$F,$P$25,$B:$B,$N29,$C:$C,Q$12) -> 16.529624
A30: ref_16_1024 | B30: 4 | C30: FIFOModified | D30: ********Proceso 1 Total accesos 1537 Total fallos 1 | E30: =VALUE(MID(A30,5,SEARCH("_",A30,5)-5)) -> 16 | F30: =VALUE(MID(A30,SEARCH("_",A30,5)+1,10)) -> 1024 | G30: =6*E30^2 -> 1536 | H30: =VALUE(MID(D30,SEARCH("fallos",D30)+7,20)) -> 1 | I30: =G30-H30 -> 1535 | J30: =H30/G30 -> 0.00065104167 | K30: =I30*0.0000001+H30*0.008 -> 0.0081535
A31: ref_16_1024 | B31: 4 | C31: LRU | D31: ********Proceso 1 Total accesos 1537 Total fallos 1 | E31: =VALUE(MID(A31,5,SEARCH("_",A31,5)-5)) -> 16 | F31: =VALUE(MID(A31,SEARCH("_",A31,5)+1,10)) -> 1024 | G31: =6*E31^2 -> 1536 | H31: =VALUE(MID(D31,SEARCH("fallos",D31)+7,20)) -> 1 | I31: =G31-H31 -> 1535 | J31: =H31/G31 -> 0.00065104167 | K31: =I31*0.0000001+H31*0.008 -> 0.0081535
A32: ref_16_1024 | B32: 8 | C32: FIFO | D32: ********Proceso 1 Total accesos 1537 Total fallos 1 | E32: =VALUE(MID(A32,5,SEARCH("_",A32,5)-5)) -> 16 | F32: =VALUE(MID(A32,SEARCH("_",A32,5)+1,10)) -> 1024 | G32: =6*E32^2 -> 1536 | H32: =VALUE(MID(D32,SEARCH("fallos",D32)+7,20)) -> 1 | I32: =G32-H32 -> 1535 | J32: =H32/G32 -> 0.00065104167 | K32: =I32*0.0000001+H32*0.008 -> 0.0081535
A33: ref_16_1024 | B33: 8 | C33: FIFOModified | D33: ********Proceso 1 Total accesos 1537 Total fallos 1 | E33: =VALUE(MID(A33,5,SEARCH("_",A33,5)-5)) -> 16 | F33: =VALUE(MID(A33,SEARCH("_",A33,5)+1,10)) -> 1024 | G33: =6*E33^2 -> 1536 | H33: =VALUE(MID(D33,SEARCH("fallos",D33)+7,20)) -> 1 | I33: =G33-H33 -> 1535 | J33: =H33/G33 -> 0.00065104167 | K33: =I33*0.0000001+H33*0.008 -> 0.0081535
A34: ref_16_1024 | B34: 8 | C34: LRU | D34: ********Proceso 1 Total accesos 1537 Total fallos 1 | E34: =VALUE(MID(A34,5,SEARCH("_",A34,5)-5)) -> 16 | F34: =VALUE(MID(A34,SEARCH("_",A34,5)+1,10)) -> 1024 | G34: =6*E34^2 -> 1536 | H34: =VALUE(MID(D34,SEARCH("fallos",D34)+7,20)) -> 1 | I34: =G34-H34 -> 1535 | J34: =H34/G34 -> 0.00065104167 | K34: =I34*0.0000001+H34*0.008 -> 0.0081535
A35: ref_16_1024 | B35: 16 | C35: FIFO | D35: ********Proceso 1 Total accesos 1537 Total fallos 1 | E35: =VALUE(MID(A35,5,SEARCH("_",A35,5)-5)) -> 16 | F35: =VALUE(MID(A35,SEARCH("_",A35,5)+1,10)) -> 1024 | G35: =6*E35^2 -> 1536 | H35: =VALUE(MID(D35,SEARCH("fallos",D35)+7,20)) -> 1 | I35: =G35-H35 -> 1535 | J35: =H35/G35 -> 0.00065104167 | K35: =I35*0.0000001+H35*0.008 -> 0.0081535
A36: ref_16_1024 | B36: 16 | C36: FIFOModified | D36: ********Proceso 1 Total accesos 1537 Total fallos 1 | E36: =VALUE(MID(A36,5,SEARCH("_",A36,5)-5)) -> 16 | F36: =VALUE(MID(A36,SEARCH("_",A36,5)+1,10)) -> 1024 | G36: =6*E36^2 -> 1536 | H36: =VALUE(MID(D36,SEARCH("fallos",D36)+7,20)) -> 1 | I36: =G36-H36 -> 1535 | J36: =H36/G36 -> 0.00065104167 | K36: =I36*0.0000001+H36*0.008 -> 0.0081535
A37: ref_16_1024 | B37: 16 | C37: LRU | D37: ********Proceso 1 Total accesos 1537 Total fallos 1 | E37: =VALUE(MID(A37,5,SEARCH("_",A37,5)-5)) -> 16 | F37: =VALUE(MID(A37,SEARCH("_",A37,5)+1,10)) -> 1024 | G37: =6*E37^2 -> 1536 | H37: =VALUE(MID(D37,SEARCH("fallos",D37)+7,20)) -> 1 | I37: =G37-H37 -> 1535 | J37: =H37/G37 -> 0.00065104167 | K37: =I37*0.0000001+H37*0.008 -> 0.0081535
A38: ref_16_256 | B38: 4 | C38: FIFO | D38: ********Proceso 1 Total accesos 1538 Total fallos 2 | E38: =VALUE(MID(A38,5,SEARCH("_",A38,5)-5)) -> 16 | F38: =VALUE(MID(A38,SEARCH("_",A38,5)+1,10)) -> 256 | G38: =6*E38^2 -> 1536 | H38: =VALUE(MID(D38,SEARCH("fallos",D38)+7,20)) -> 2 | I38: =G38-H38 -> 1534 | J38: =H38/G38 -> 0.0013020833 | K38: =I38*0.0000001+H38*0.008 -> 0.0161534
A39: ref_16_256 | B39: 4 | C39: FIFOModified | D39: ********Proceso 1 Total accesos 1538 Total fallos 2 | E39: =VALUE(MID(A39,5,SEARCH("_",A39,5)-5)) -> 16 | F39: =VALUE(MID(A39,SEARCH("_",A39,5)+1,10)) -> 256 | G39: =6*E39^2 -> 1536 | H39: =VALUE(MID(D39,SEARCH("fallos",D39)+7,20)) -> 2 | I39: =G39-H39 -> 1534 | J39: =H39/G39 -> 0.0013020833 | K39: =I39*0.0000001+H39*0.008 -> 0.0161534
A40: ref_16_256 | B40: 4 | C40: LRU | D40: ********Proceso 1 Total accesos 1538 Total fallos 2 | E40: =VALUE(MID(A40,5,SEARCH("_",A40,5)-5)) -> 16 | F40: =VALUE(MID(A40,SEARCH("_",A40,5)+1,10)) -> 256 | G40: =6*E40^2 -> 1536 | H40: =VALUE(MID(D40,SEARCH("fallos",D40)+7,20)) -> 2 | I40: =G40-H40 -> 1534 | J40: =H40/G40 -> 0.0013020833 | K40: =I40*0.0000001+H40*0.008 -> 0.0161534
...

Sheet 8_64
A1: Matriz | B1: 8 | C1: TP | D1: 64
B2: FIFO | C2: FIFOModified | D2: LRU
A3: 4 | B3: =SUMIFS(Datos!$H:$H,Datos!$E:$E,$B$1,Datos!$F:$F,$D$1,Datos!$B:$B,$A3,Datos!$C:$C,B$2) -> 2 | C3: =SUMIFS(Datos!$H:$H,Datos!$E:$E,$B$1,Datos!$F:$F,$D$1,Datos!$B:$B,$A3,Datos!$C:$C,C$2) -> 2 | D3: =SUMIFS(Datos!$H:$H,Datos!$E:$E,$B$1,Datos!$F:$F,$D$1,Datos!$B:$B,$A3,Datos!$C:$C,D$2) -> 2
A4: 8 | B4: =SUMIFS(Datos!$H:$H,Datos!$E:$E,$B$1,Datos!$F:$F,$D$1,Datos!$B:$B,$A4,Datos!$C:$C,B$2) -> 2 | C4: =SUMIFS(Datos!$H:$H,Datos!$E:$E,$B$1,Datos!$F:$F,$D$1,Datos!$B:$B,$A4,Datos!$C:$C,C$2) -> 2 | D4: =SUMIFS(Datos!$H:$H,Datos!$E:$E,$B$1,Datos!$F:$F,$D$1,Datos!$B:$B,$A4,Datos!$C:$C,D$2) -> 2
A5: 16 | B5: =SUMIFS(Datos!$H:$H,Datos!$E:$E,$B$1,Datos!$F:$F,$D$1,Datos!$B:$B,$A5,Datos!$C:$C,B$2) -> 2 | C5: =SUMIFS(Datos!$H:$H,Datos!$E:$E,$B$1,Datos!$F:$F,$D$1,Datos!$B:$B,$A5,Datos!$C:$C,C$2) -> 2 | D5: =SUMIFS(Datos!$H:$H,Datos!$E:$E,$B$1,Datos!$F:$F,$D$1,Datos!$B:$B,$A5,Datos!$C:$C,D$2) -> 2

Sheet 8_256
A1: Matriz | B1: 8 | C1: TP | D1: 256
B2: FIFO | C2: FIFOModified | D2: LRU
A3: 4 | B3: =SUMIFS(Datos!$H:$H,Datos!$E:$E,$B$1,Datos!$F:$F,$D$1,Datos!$B:$B,$A3,Datos!$C:$C,B$2) -> 1 | C3: =SUMIFS(Datos!$H:$H,Datos!$E:$E,$B$1,Datos!$F:$F,$D$1,Datos!$B:$B,$A3,Datos!$C:$C,C$2) -> 1 | D3: =SUMIFS(Datos!$H:$H,Datos!$E:$E,$B$1,Datos!$F:$F,$D$1,Datos!$B:$B,$A3,Datos!$C:$C,D$2) -> 1
A4: 8 | B4: =SUMIFS(Datos!$H:$H,Datos!$E:$E,$B$1,Datos!$F:$F,$D$1,Datos!$B:$B,$A4,Datos!$C:$C,B$2) -> 1 | C4: =SUMIFS(Datos!$H:$H,Datos!$E:$E,$B$1,Datos!$F:$F,$D$1,Datos!$B:$B,$A4,Datos!$C:$C,C$2) -> 1 | D4: =SUMIFS(Datos!$H:$H,Datos!$E:$E,$B$1,Datos!$F:$F,$D$1,Datos!$B:$B,$A4,Datos!$C:$C,D$2) -> 1
A5: 16 | B5: =SUMIFS(Datos!$H:$H,Datos!$E:$E,$B$1,Datos!$F:$F,$D$1,Datos!$B:$B,$A5,Datos!$C:$C,B$2) -> 1 | C5: =SUMIFS(Datos!$H:$H,Datos!$E:$E,$B$1,Datos!$F:$F,$D$1,Datos!$B:$B,$A5,Datos!$C:$C,C$2) -> 1 | D5: =SUMIFS(Datos!$H:$H,Datos!$E:$E,$B$1,Datos!$F:$F,$D$1,Datos!$B:$B,$A5,Datos!$C:$C,D$2) -> 1

Sheet 8_1024
A1: Matriz | B1: 8 | C1: TP | D1: 1024
B2: FIFO | C2: FIFOModified | D2: LRU
A3: 4 | B3: =SUMIFS(Datos!$H:$H,Datos!$E:$E,$B$1,Datos!$F:$F,$D$1,Datos!$B:$B,$A3,Datos!$C:$C,B$2) -> 1 | C3: =SUMIFS(Datos!$H:$H,Datos!$E:$E,$B$1,Datos!$F:$F,$D$1,Datos!$B:$B,$A3,Datos!$C:$C,C$2) -> 1 | D3: =SUMIFS(Datos!$H:$H,Datos!$E:$E,$B$1,Datos!$F:$F,$D$1,Datos!$B:$B,$A3,Datos!$C:$C,D$2) -> 1
A4: 8 | B4: =SUMIFS(Datos!$H:$H,Datos!$E:$E,$B$1,Datos!$F:$F,$D$1,Datos!$B:$B,$A4,Datos!$C:$C,B$2) -> 1 | C4: =SUMIFS(Datos!$H:$H,Datos!$E:$E,$B$1,Datos!$F:$F,$D$1,Datos!$B:$B,$A4,Datos!$C:$C,C$2) -> 1 | D4: =SUMIFS(Datos!$H:$H,Datos!$E:$E,$B$1,Datos!$F:$F,$D$1,Datos!$B:$B,$A4,Datos!$C:$C,D$2) -> 1
A5: 16 | B5: =SUMIFS(Datos!$H:$H,Datos!$E:$E,$B$1,Datos!$F:$F,$D$1,Datos!$B:$B,$A5,Datos!$C:$C,B$2) -> 1 | C5: =SUMIFS(Datos!$H:$H,Datos!$E:$E,$B$1,Datos!$F:$F,$D$1,Datos!$B:$B,$A5,Datos!$C:$C,C$2) -> 1 | D5: =SUMIFS(Datos!$H:$H,Datos!$E:$E,$B$1,Datos!$F:$F,$D$1,Datos!$B:$B,$A5,Datos!$C:$C,D$2) -> 1

Sheet 16_64
A1: Matriz | B1: 16 | C1: TP | D1: 64
B2: FIFO | C2: FIFOModified | D2: LRU
A3: 4 | B3: =SUMIFS(Datos!$H:$H,Datos!$E:$E,$B$1,Datos!$F:$F,$D$1,Datos!$B:$B,$A3,Datos!$C:$C,B$2) -> 85 | C3: =SUMIFS(Datos!$H:$H,Datos!$E:$E,$B$1,Datos!$F:$F,$D$1,Datos!$B:$B,$A3,Datos!$C:$C,C$2) -> 69 | D3: =SUMIFS(Datos!$H:$H,Datos!$E:$E,$B$1,Datos!$F:$F,$D$1,Datos!$B:$B,$A3,Datos!$C:$C,D$2) -> 69
A4: 8 | B4: =SUMIFS(Datos!$H:$H,Datos!$E:$E,$B$1,Datos!$F:$F,$D$1,Datos!$B:$B,$A4,Datos!$C:$C,B$2) -> 5 | C4: =SUMIFS(Datos!$H:$H,Datos!$E:$E,$B$1,Datos!$F:$F,$D$1,Datos!$B:$B,$A4,Datos!$C:$C,C$2) -> 5 | D4: =SUMIFS(Datos!$H:$H,Datos!$E:$E,$B$1,Datos!$F:$F,$D$1,Datos!$B:$B,$A4,Datos!$C:$C,D$2) -> 5
A5: 16 | B5: =SUMIFS(Datos!$H:$H,Datos!$E:$E,$B$1,Datos!$F:$F,$D$1,Datos!$B:$B,$A5,Datos!$C:$C,B$2) -> 5 | C5: =SUMIFS(Datos!$H:$H,Datos!$E:$E,$B$1,Datos!$F:$F,$D$1,Datos!$B:$B,$A5,Datos!$C:$C,C$2) -> 5 | D5: =SUMIFS(Datos!$H:$H,Datos!$E:$E,$B$1,Datos!$F:$F,$D$1,Datos!$B:$B,$A5,Datos!$C:$C,D$2) -> 5

Sheet 16_256
A1: Matriz | B1: 16 | C1: TP | D1: 256
B2: FIFO | C2: FIFOModified | D2: LRU
A3: 4 | B3: =SUMIFS(Datos!$H:$H,Datos!$E:$E,$B$1,Datos!$F:$F,$D$1,Datos!$B:$B,$A3,Datos!$C:$C,B$2) -> 2 | C3: =SUMIFS(Datos!$H:$H,Datos!$E:$E,$B$1,Datos!$F:$F,$D$1,Datos!$B:$B,$A3,Datos!$C:$C,C$2) -> 2 | D3: =SUMIFS(Datos!$H:$H,Datos!$E:$E,$B$1,Datos!$F:$F,$D$1,Datos!$B:$B,$A3,Datos!$C:$C,D$2) -> 2
A4: 8 | B4: =SUMIFS(Datos!$H:$H,Datos!$E:$E,$B$1,Datos!$F:$F,$D$1,Datos!$B:$B,$A4,Datos!$C:$C,B$2) -> 2 | C4: =SUMIFS(Datos!$H:$H,Datos!$E:$E,$B$1,Datos!$F:$F,$D$1,Datos!$B:$B,$A4,Datos!$C:$C,C$2) -> 2 | D4: =SUMIFS(Datos!$H:$H,Datos!$E:$E,$B$1,Datos!$F:$F,$D$1,Datos!$B:$B,$A4,Datos!$C:$C,D$2) -> 2
A5: 16 | B5: =SUMIFS(Datos!$H:$H,Datos!$E:$E,$B$1,Datos!$F:$F,$D$1,Datos!$B:$B,$A5,Datos!$C:$C,B$2) -> 2 | C5: =SUMIFS(Datos!$H:$H,Datos!$E:$E,$B$1,Datos!$F:$F,$D$1,Datos!$B:$B,$A5,Datos!$C:$C,C$2) -> 2 | D5: =SUMIFS(Datos!$H:$H,Datos!$E:$E,$B$1,Datos!$F:$F,$D$1,Datos!$B:$B,$A5,Datos!$C:$C,D$2) -> 2

Sheet 16_1024
A1: Matriz | B1: 16 | C1: TP | D1: 1024
B2: FIFO | C2: FIFOModified | D2: LRU
A3: 4 | B3: =SUMIFS(Datos!$H:$H,Datos!$E:$E,$B$1,Datos!$F:$F,$D$1,Datos!$B:$B,$A3,Datos!$C:$C,B$2) -> 1 | C3: =SUMIFS(Datos!$H:$H,Datos!$E:$E,$B$1,Datos!$F:$F,$D$1,Datos!$B:$B,$A3,Datos!$C:$C,C$2) -> 1 | D3: =SUMIFS(Datos!$H:$H,Datos!$E:$E,$B$1,Datos!$F:$F,$D$1,Datos!$B:$B,$A3,Datos!$C:$C,D$2) -> 1
A4: 8 | B4: =SUMIFS(Datos!$H:$H,Datos!$E:$E,$B$1,Datos!$F:$F,$D$1,Datos!$B:$B,$A4,Datos!$C:$C,B$2) -> 1 | C4: =SUMIFS(Datos!$H:$H,Datos!$E:$E,$B$1,Datos!$F:$F,$D$1,Datos!$B:$B,$A4,Datos!$C:$C,C$2) -> 1 | D4: =SUMIFS(Datos!$H:$H,Datos!$E:$E,$B$1,Datos!$F:$F,$D$1,Datos!$B:$B,$A4,Datos!$C:$C,D$2) -> 1
A5: 16 | B5: =SUMIFS(Datos!$H:$H,Datos!$E:$E,$B$1,Datos!$F:$F,$D$1,Datos!$B:$B,$A5,Datos!$C:$C,B$2) -> 1 | C5: =SUMIFS(Datos!$H:$H,Datos!$E:$E,$B$1,Datos!$F:$F,$D$1,Datos!$B:$B,$A5,Datos!$C:$C,C$2) -> 1 | D5: =SUMIFS(Datos!$H:$H,Datos!$E:$E,$B$1,Datos!$F:$F,$D$1,Datos!$B:$B,$A5,Datos!$C:$C,D$2) -> 1

Sheet 128_64
A1: Matriz | B1: 128 | C1: TP | D1: 64
B2: FIFO | C2: FIFOModified | D2: LRU
A3: 4 | B3: =SUMIFS(Datos!$H:$H,Datos!$E:$E,$B$1,Datos!$F:$F,$D$1,Datos!$B:$B,$A3,Datos!$C:$C,B$2) -> 20864 | C3: =SUMIFS(Datos!$H:$H,Datos!$E:$E,$B$1,Datos!$F:$F,$D$1,Datos!$B:$B,$A3,Datos!$C:$C,C$2) -> 17152 | D3: =SUMIFS(Datos!$H:$H,Datos!$E:$E,$B$1,Datos!$F:$F,$D$1,Datos!$B:$B,$A3,Datos!$C:$C,D$2) -> 17152
A4: 8 | B4: =SUMIFS(Datos!$H:$H,Datos!$E:$E,$B$1,Datos!$F:$F,$D$1,Datos!$B:$B,$A4,Datos!$C:$C,B$2) -> 18752 | C4: =SUMIFS(Datos!$H:$H,Datos!$E:$E,$B$1,Datos!$F:$F,$D$1,Datos!$B:$B,$A4,Datos!$C:$C,C$2) -> 16897 | D4: =SUMIFS(Datos!$H:$H,Datos!$E:$E,$B$1,Datos!$F:$F,$D$1,Datos!$B:$B,$A4,Datos!$C:$C,D$2) -> 16897
A5: 16 | B5: =SUMIFS(Datos!$H:$H,Datos!$E:$E,$B$1,Datos!$F:$F,$D$1,Datos!$B:$B,$A5,Datos!$C:$C,B$2) -> 17696 | C5: =SUMIFS(Datos!$H:$H,Datos!$E:$E,$B$1,Datos!$F:$F,$D$1,Datos!$B:$B,$A5,Datos!$C:$C,C$2) -> 16897 | D5: =SUMIFS(Datos!$H:$H,Datos!$E:$E,$B$1,Datos!$F:$F,$D$1,Datos!$B:$B,$A5,Datos!$C:$C,D$2) -> 16897

Sheet 128_256
A1: Matriz | B1: 128 | C1: TP | D1: 256
B2: FIFO | C2: FIFOModified | D2: LRU
A3: 4 | B3: =SUMIFS(Datos!$H:$H,Datos!$E:$E,$B$1,Datos!$F:$F,$D$1,Datos!$B:$B,$A3,Datos!$C:$C,B$2) -> 10320 | C3: =SUMIFS(Datos!$H:$H,Datos!$E:$E,$B$1,Datos!$F:$F,$D$1,Datos!$B:$B,$A3,Datos!$C:$C,C$2) -> 8257 | D3: =SUMIFS(Datos!$H:$H,Datos!$E:$E,$B$1,Datos!$F:$F,$D$1,Datos!$B:$B,$A3,Datos!$C:$C,D$2) -> 8257
A4: 8 | B4: =SUMIFS(Datos!$H:$H,Datos!$E:$E,$B$1,Datos!$F:$F,$D$1,Datos!$B:$B,$A4,Datos!$C:$C,B$2) -> 9288 | C4: =SUMIFS(Datos!$H:$H,Datos!$E:$E,$B$1,Datos!$F:$F,$D$1,Datos!$B:$B,$A4,Datos!$C:$C,C$2) -> 8257 | D4: =SUMIFS(Datos!$H:$H,Datos!$E:$E,$B$1,Datos!$F:$F,$D$1,Datos!$B:$B,$A4,Datos!$C:$C,D$2) -> 8257
A5: 16 | B5: =SUMIFS(Datos!$H:$H,Datos!$E:$E,$B$1,Datos!$F:$F,$D$1,Datos!$B:$B,$A5,Datos!$C:$C,B$2) -> 8772 | C5: =SUMIFS(Datos!$H:$H,Datos!$E:$E,$B$1,Datos!$F:$F,$D$1,Datos!$B:$B,$A5,Datos!$C:$C,C$2) -> 8257 | D5: =SUMIFS(Datos!$H:$H,Datos!$E:$E,$B$1,Datos!$F:$F,$D$1,Datos!$B:$B,$A5,Datos!$C:$C,D$2) -> 8257

Sheet 128_1024
A1: Matriz | B1: 128 | C1: TP | D1: 1024
B2: FIFO | C2: FIFOModified | D2: LRU
A3: 4 | B3: =SUMIFS(Datos!$H:$H,Datos!$E:$E,$B$1,Datos!$F:$F,$D$1,Datos!$B:$B,$A3,Datos!$C:$C,B$2) -> 2580 | C3: =SUMIFS(Datos!$H:$H,Datos!$E:$E,$B$1,Datos!$F:$F,$D$1,Datos!$B:$B,$A3,Datos!$C:$C,C$2) -> 2065 | D3: =SUMIFS(Datos!$H:$H,Datos!$E:$E,$B$1,Datos!$F:$F,$D$1,Datos!$B:$B,$A3,Datos!$C:$C,D$2) -> 2065
A4: 8 | B4: =SUMIFS(Datos!$H:$H,Datos!$E:$E,$B$1,Datos!$F:$F,$D$1,Datos!$B:$B,$A4,Datos!$C:$C,B$2) -> 2322 | C4: =SUMIFS(Datos!$H:$H,Datos!$E:$E,$B$1,Datos!$F:$F,$D$1,Datos!$B:$B,$A4,Datos!$C:$C,C$2) -> 2065 | D4: =SUMIFS(Datos!$H:$H,Datos!$E:$E,$B$1,Datos!$F:$F,$D$1,Datos!$B:$B,$A4,Datos!$C:$C,D$2) -> 2065
A5: 16 | B5: =SUMIFS(Datos!$H:$H,Datos!$E:$E,$B$1,Datos!$F:$F,$D$1,Datos!$B:$B,$A5,Datos!$C:$C,B$2) -> 2193 | C5: =SUMIFS(Datos!$H:$H,Datos!$E:$E,$B$1,Datos!$F:$F,$D$1,Datos!$B:$B,$A5,Datos!$C:$C,C$2) -> 2065 | D5: =SUMIFS(Datos!$H:$H,Datos!$E:$E,$B$1,Datos!$F:$F,$D$1,Datos!$B:$B,$A5,Datos!$C:$C,D$2) -> 2065
